Workbook

Sheet Go-Karts pricelist 2026
D3: Valid as per 1 January 2026
D5: Dealerprice
A6: Art. nr. | B6: Description | C6: EAN-code | D6: excl. VAT
B7: BERG Buzzy
A8: 24.30.08.00 | B8: BERG Buzzy Orange | C8: 8715839100372 | D8: 72.666667
A9: 24.30.15.00 | B9: BERG Buzzy Retro Green | C9: 8715839091182 | D9: 92.666667
A10: 24.30.01.00 | B10: BERG Buzzy Nitro | C10: 8715839059427 | D10: 92.666667
A11: 24.30.02.00 | B11: BERG Buzzy Bloom | C11: 8715839059434 | D11: 92.666667
A12: 24.32.00.00 | B12: BERG Buzzy Nitro 2-in-1 | C12: 8715839068320 | D12: 112.66667
A13: 24.32.02.00 | B13: BERG Buzzy Retro 2-in-1 Green | C13: 8715839075991 | D13: 112.66667
A14: 24.30.12.00 | B14: JEEP Buzzy Sahara | C14: 8715839066661 | D14: 112.66667
A15: 24.30.16.00 | B15: BERG Buzzy Green | C15: 8715839105063 | D15: 79.333333
A16: 24.30.17.00 | B16: BERG Buzzy Pink | C16: 8715839105100 | D16: 92.666667
A17: 24.30.22.00 | B17: BERG Buzzy Police | C17: 8715839086102 | D17: 119.33333
A18: 24.30.11.00 | B18: BERG Buzzy John Deere | C18: 8715839057744 | D18: 119.33333
B19: BERG Reppy
A20: 24.60.07.00 | B20: BERG Reppy Blue | C20: 8715839101522 | D20: 132.66667
A21: 24.60.04.00 | B21: BERG Reppy Roadster | C21: 8715839075328 | D21: 139.33333
A22: 24.60.02.00 | B22: BERG Reppy Rebel | C22: 8715839066630 | D22: 146
A23: 24.61.01.00 | B23: BERG Reppy GP | C23: 8715839081893 | D23: 172.66667
A24: 24.61.00.00 | B24: BERG Reppy BMW | C24: 8715839068993 | D24: 179.33333
A25: 24.60.09.00 | B25: BERG Reppy Volt Black | C25: 8715839105087 | D25: 172.66667
B26: BERG Buddy
A27: 24.20.60.03 | B27: BERG Buddy B-Orange | C27: 8715839067705 | D27: 199.33333
A28: 24.20.64.01 | B28: BERG Buddy Lua | C28: 8715839068207 | D28: 212.66667
A29: 24.20.65.01 | B29: BERG Buddy Cross | C29: 8715839062472 | D29: 219.33333
A30: 24.20.68.00 | B30: BERG Buddy Retro Green | C30: 8715839101799 | D30: 212.66667
A31: 24.20.69.00 | B31: BERG Buddy Trail Green | C31: 8715839105070 | D31: 212.66667
A32: 24.20.70.00 | B32: BERG Buddy Cross Black | C32: 8715839105377 | D32: 219.33333
A33: 24.20.71.00 | B33: BERG Buddy Purple | C33: 8715839105414 | D33: 212.66667
A34: 24.21.24.03 | B34: BERG Buddy John Deere | C34: 8715839100419 | D34: 266
A35: 24.21.34.03 | B35: Jeep® Buddy Wrangler | C35: 8715839100044 | D35: 266
A36: 24.21.54.02 | B36: BERG Buddy Fendt | C36: 8715839100426 | D36: 266
A37: 24.15.01.01 | B37: BERG Choppy Neo | C37: 8715839070187 | D37: 186
A38: 24.20.66.00 | B38: BERG Buddy PRO | C38: 8715839053692 | D38: 322
B39: BERG Rally
A40: 24.40.01.00 | B40: BERG Rally NRG Orange | C40: 8715839082012 | D40: 306
A41: 24.40.02.00 | B41: BERG Rally APX Blue | C41: 8715839081992 | D41: 352.66667
A42: 24.40.03.00 | B42: BERG Rally DRT Green | C42: 8715839086072 | D42: 332.66667
A43: 24.40.11.00 | B43: Jeep® Rally Cherokee | C43: 8715839086096 | D43: 379.33333
...

Sheet Ride-Ons pricelist 2026
D3: Valid as per 1 January 2026
D5: inkoopprijs
D6: Dealerprice
A7: Art. nr. | B7: Description | C7: EAN-code | D7: excl. VAT
B8: BERG GO
A9: 24.52.00.00 | B9: BERG GO Twirl Turquoise | C9: 8715839085334 | D9: 39.333333
A10: 24.52.01.00 | B10: BERG GO Twirl Multicolor | C10: 8715839085341 | D10: 39.333333
B11: BERG GO²
A12: 24.50.00.00 | B12: BERG GO² Blue | C12: 8715839065404 | D12: 46
A13: 24.50.01.00 | B13: BERG GO² Pink | C13: 8715839064322 | D13: 46
A14: 24.50.04.00 | B14: BERG GO² SparX Yellow | C14: 8715839070460 | D14: 66
A15: 24.50.07.00 | B15: BERG GO² Retro Pink | C15: 8715839076028 | D15: 66
A16: 24.50.08.00 | B16: BERG GO² Retro Green | C16: 8715839076035 | D16: 66
B17: BERG Moov
A18: 24.81.00.00 | B18: BERG MOOV 10 Blue | C18: 8715839102475 | D18: 39.333333
A19: 24.81.01.00 | B19: BERG MOOV 10 Green | C19: 8715839102482 | D19: 39.333333
A20: 24.81.02.00 | B20: BERG MOOV 10 Pink | C20: 8715839102499 | D20: 39.333333
A21: 24.81.03.00 | B21: BERG MOOV 10 Sand Beige | C21: 8715839105223 | D21: 39.333333
A22: 24.82.00.00 | B22: BERG MOOV 12 Sage Green | C22: 8715839105865 | D22: 52.666667
A23: 24.82.01.00 | B23: BERG MOOV 12 Lavender Purple | C23: 8715839105872 | D23: 52.666667
A24: 24.82.02.00 | B24: BERG MOOV 12 Sand Beige | C24: 8715839105889 | D24: 52.666667
A25: 24.82.03.00 | B25: BERG MOOV 12 Retro Black | C25: 8715839105896 | D25: 59.333333
A26: 24.82.04.00 | B26: BERG MOOV 12 Retro Pink | C26: 8715839105902 | D26: 59.333333
B27: BERG Biky
A28: 24.75.72.00 | B28: BERG Biky Cross Grey | C28: 8715839077810 | D28: 96.666667
A29: 24.75.50.00 | B29: BERG Biky Retro Green | C29: 8715839077773 | D29: 90
A30: 24.75.51.00 | B30: BERG Biky Retro Pink | C30: 8715839077780 | D30: 90
A31: 24.74.70.00 | B31: BERG Biky Cross Blue Handbrake | C31: 8715839085358 | D31: 110
A32: 24.74.71.00 | B32: BERG Biky Cross Grey Handbrake | C32: 8715839085365 | D32: 110
A33: 24.74.72.00 | B33: BERG Biky Trail Green Handbrake | C33: 8715839090819 | D33: 123.33333
A34: 24.74.73.00 | B34: BERG Biky Cross Black Handbrake | C34: 8715839100310 | D34: 110
A35: 24.74.74.00 | B35: BERG Biky Cross White Handbrake | C35: 8715839100655 | D35: 110
A36: 24.74.75.00 | B36: BERG Biky Cross Purple Handbrake | C36: 8715839100662 | D36: 110
A37: 24.74.76.00 | B37: BERG Biky Cross Green Handbrake | C37: 8715839103366 | D37: 110
A38: 24.74.77.00 | B38: BERG Biky Trail Sand Handbrake | C38: 8715839103373 | D38: 123.33333
A39: 24.74.78.00 | B39: BERG Biky Cross Red Handbrake | C39: 8715839105216 | D39: 110
B40: BERG Nexo
A41: 24.77.00.00 | B41: BERG Nexo Foldable Lime | C41: 8715839090529 | D41: 52.666667
A42: 24.77.01.00 | B42: BERG Nexo Foldable Blue | C42: 8715839090536 | D42: 52.666667
A43: 24.77.02.00 | B43: BERG Nexo Foldable Red | C43: 8715839090543 | D43: 52.666667
...

Sheet Trampoline pricelist 2026
A1: Pricelist Trampolines
D2: Valid as per 1 January 2026
A4: Art. nr. | B4: Description | C4: EAN-code | D4: Dealerprice
B5: Trampoline Regular + Safety net | D5: excl. VAT
B6: BERG Favorit - Regular + Safety Net Comfort
A7: 35.07.33.02 | B7: BERG Favorit Regular 200 Grey + Safety Net Comfort | C7: 8715839102512 | D7: 272.66667
A8: 35.09.33.02 | B8: BERG Favorit Regular 270 Grey + Safety Net Comfort | C8: 8715839102543 | D8: 359.33333
A9: 35.11.33.02 | B9: BERG Favorit Regular 330 Grey + Safety Net Comfort | C9: 8715839102581 | D9: 439.33333
A10: 35.11.37.02 | B10: BERG Favorit Regular 330 Green + Safety Net Comfort | C10: 8715839102598 | D10: 439.33333
A11: 35.12.94.03 | B11: BERG Favorit Regular 380 Grey + Safety Net Comfort | C11: 8715839102680 | D11: 512.66667
A12: 35.12.95.04 | B12: BERG Favorit Regular 380 Black + Safety Net Comfort | C12: 8715839102697 | D12: 526
A13: 35.12.01.05 | B13: BERG Favorit Regular 380 Green + Safety Net Comfort | C13: 8715839102703 | D13: 512.66667
A14: 35.14.94.03 | B14: BERG Favorit Regular 430 Grey + Safety Net Comfort | C14: 8715839102802 | D14: 579.33333
A15: 35.14.95.04 | B15: BERG Favorit Regular 430 Black + Safety Net Comfort | C15: 8715839102826 | D15: 592.66667
A16: 35.14.02.05 | B16: BERG Favorit Regular 430 Green + Safety Net Comfort | C16: 8715839102833 | D16: 579.33333
A17: 35.14.99.03 | B17: BERG Favorit Regular 430 Grey Levels + Safety Net Comfort | C17: 8715839102840 | D17: 612.66667
B18: BERG Champion - Regular + Safety Net Deluxe
A19: 35.41.93.04 | B19: BERG Champion Regular 330 Grey + Safety Net Deluxe | C19: 8715839101065 | D19: 746
A20: 35.42.93.04 | B20: BERG Champion Regular 380 Grey + Safety Net Deluxe | C20: 8715839101072 | D20: 839.33333
A21: 35.44.93.04 | B21: BERG Champion Regular 430 Grey + Safety Net Deluxe | C21: 8715839101089 | D21: 926
A22: 35.44.99.04 | B22: BERG Champion Regular 430 Grey Levels + Safety Net Deluxe | C22: 8715839101096 | D22: 952.66667
A23: 35.44.88.02 | B23: BERG Champion Regular 430 Grey + Safety Net DLX XL | C23: 8715839101492 | D23: 986
A24: 35.44.89.02 | B24: BERG Champion Regular 430 Grey Levels + Safety Net DLX XL | C24: 8715839101102 | D24: 1026
B25: BERG Elite - Regular + Safety Net Deluxe
A26: 37.81.03.03 | B26: BERG Elite Regular 330 Grey + Safety Net Deluxe | C26: 8715839101119 | D26: 966
A27: 37.82.03.03 | B27: BERG Elite Regular 380 Grey + Safety Net Deluxe | C27: 8715839101126 | D27: 1092.6667
A28: 37.84.03.03 | B28: BERG Elite Regular 430 Grey + Safety Net Deluxe | C28: 8715839101133 | D28: 1172.6667
A29: 37.84.13.04 | B29: BERG Elite Regular 430 Grey Levels + Safety Net Deluxe | C29: 8715839101140 | D29: 1212.6667
A30: 37.84.23.02 | B30: BERG Elite Regular 430 Grey + Safety Net DLX XL | C30: 8715839101157 | D30: 1232.6667
A31: 37.84.33.02 | B31: BERG Elite Regular 430 Grey Levels + Safety Net DLX XL | C31: 8715839101164 | D31: 1279.3333
B32: BERG Grand Favorit - Regular + Safety Net Comfort
A33: 30.25.65.33 | B33: BERG Grand Favorit Regular 520 Grey + Safety Net Comfort | C33: 8715839102963 | D33: 719.33333
A34: 30.25.65.42 | B34: BERG Grand Favorit Regular 520 Black + Safety Net Comfort | C34: 8715839102970 | D34: 732.66667
A35: 30.25.65.73 | B35: BERG Grand Favorit Regular 520 Green + Safety Net Comfort | C35: 8715839102987 | D35: 719.33333
B36: BERG Grand Champion - Regular + Safety Net Deluxe
A37: 30.35.73.32 | B37: BERG Grand Champion Regular 350 Grey + Safety Net Deluxe | C37: 8715839101171 | D37: 852.66667
A38: 30.35.74.32 | B38: BERG Grand Champion Regular 470 Grey + Safety Net Deluxe | C38: 8715839101188 | D38: 932.66667
A39: 30.35.75.33 | B39: BERG Grand Champion Regular 520 Grey + Safety Net Deluxe | C39: 8715839101195 | D39: 1012.6667
A40: 30.35.95.32 | B40: BERG Grand Champion Regular 520 Grey + Safety Net DLX XL | C40: 8715839101201 | D40: 1092.6667
B41: BERG Grand Elite - Regular + Safety Net Deluxe
...

Sheet Play pricelist 2026
A1: PLAY
A3: Selective distrubution | D3: Valid as per 1 January 2026
D6: Dealerprice
A7: Art. nr. | B7: Description | C7: EAN-code | D7: excl. VAT
B8: BERG PlayBase Wall
A9: 22.00.01.00 | B9: BERG PlayBase Wall | C9: 8715839102345 | D9: 666
A10: 22.00.02.00 | B10: BERG PlayBase Wall Green | C10: 8715839105131 | D10: 666
A11: 22.01.02.00 | B11: BERG PlayBase Wall + Swing set | C11: 8715839104417 | D11: 692
A12: 22.01.03.00 | B12: BERG PlayBase Wall + Family set | C12: 8715839104424 | D12: 752
A13: 22.01.04.00 | B13: BERG PlayBase Wall + Peak set | C13: 8715839104431 | D13: 951.33
A14: 22.01.05.00 | B14: BERG PlayBase Wall + Sports set | C14: 8715839104448 | D14: 818
B15: BERG Playbase Medium
A16: 22.20.01.00 | B16: BERG PlayBase Medium | C16: 8715839081824 | D16: 999.33
A17: 22.20.04.00 | B17: BERG PlayBase Medium Green | C17: 8715839105148 | D17: 999.33
A18: 22.22.00.00 | B18: BERG PlayBase Medium TL (Climbing net M+Boxing bag) | C18: 8715839081749 | D18: 1231.33
A19: 22.21.05.00 | B19: BERG PlayBase Medium + Swing set | C19: 8715839104455 | D19: 1051.33
A20: 22.21.06.00 | B20: BERG PlayBase Medium + Active set | C20: 8715839104462 | D20: 1044.67
A21: 22.21.07.00 | B21: BERG PlayBase Medium + Toddler set | C21: 8715839104479 | D21: 1091.33
A22: 22.21.08.00 | B22: BERG PlayBase Medium + Ultimate set | C22: 8715839104486 | D22: 1443.33
A23: 22.21.09.00 | B23: BERG PlayBase Medium + Play set | C23: 8715839104493 | D23: 1350.67
A24: 22.22.01.00 | B24: BERG PlayBase Medium + Sports set | C24: 8715839104509 | D24: 1250
B25: BERG Playbase Large
A26: 22.40.01.00 | B26: BERG PlayBase Large | C26: 8715839081855 | D26: 1166
A27: 22.40.05.00 | B27: BERG PlayBase Large Green | C27: 8715839103731 | D27: 1166
A28: 22.42.00.00 | B28: BERG PlayBase Large TL (Climbing net L+Boxing bag) | C28: 8715839081800 | D28: 1464.67
A29: 22.43.00.00 | B29: BERG PlayBase Large TT (Hammock) | C29: 8715839081763 | D29: 1152
A30: 22.41.04.00 | B30: BERG PlayBase Large + Toddler set | C30: 8715839104516 | D30: 1277.33
A31: 22.41.05.00 | B31: BERG PlayBase Large + Family set | C31: 8715839104523 | D31: 1318
A32: 22.41.06.00 | B32: BERG PlayBase Large + Peak set | C32: 8715839104530 | D32: 1477.33
A33: 22.41.07.00 | B33: BERG PlayBase Large + Ultimate set | C33: 8715839104547 | D33: 1670
A34: 22.41.08.00 | B34: BERG PlayBase Large + Play set | C34: 8715839104554 | D34: 1477.33
A35: 22.42.01.00 | B35: BERG PlayBase Large + Sports set | C35: 8715839104561 | D35: 1449.33
B36: BERG PlayBase Extra Large
A37: 22.60.00.00 | B37: BERG PlayBase Extra Large | C37: 8715839102338 | D37: 1332.67
A38: 22.60.01.00 | B38: BERG PlayBase Extra Large Green | C38: 8715839105155 | D38: 1332.67
A39: 22.61.00.00 | B39: BERG PlayBase Extra Large + Active set | C39: 8715839104578 | D39: 1423.33
A40: 22.61.01.00 | B40: BERG PlayBase Extra Large + Family set | C40: 8715839104585 | D40: 1457.33
A41: 22.61.02.00 | B41: BERG PlayBase Extra Large + Ultimate set | C41: 8715839104592 | D41: 1843.33
A42: 22.61.03.00 | B42: BERG PlayBase Extra Large + Play set | C42: 8715839104608 | D42: 1995.33
A43: 22.62.00.00 | B43: BERG PlayBase Extra Large + Sports set | C43: 8715839104615 | D43: 1616
...

Sheet Sports pricelist 2026
A1: SPORTS
D3: Valid as per 1 January 2026
D5: inkoopprijs
D6: Dealerprice
A7: Art. nr. | B7: Omschrijving | C7: EAN-code | D7: excl. VAT
B8: BERG SportsGoal
A9: 20.30.01.00 | B9: BERG SportsGoal S | C9: 8715839090741 | D9: 112.67
A10: 20.30.02.00 | B10: BERG SportsGoal M | C10: 8715839090758 | D10: 146
A11: 20.30.03.00 | B11: BERG SportsGoal L | C11: 8715839091823 | D11: 199.33
A12: 20.31.01.00 | B12: BERG SportsGoal Target Net S | C12: 8715839091830 | D12: 26
A13: 20.31.02.00 | B13: BERG SportsGoal Target Net M | C13: 8715839091847 | D13: 32.67
A14: 20.31.03.00 | B14: BERG SportsGoal Target Net L | C14: 8715839091854 | D14: 39.33
A15: 20.31.10.00 | B15: BERG Soccer Ball Size 5 | C15: 8715839091861 | D15: 19.33
B16: BERG SportsGoal Kits
A17: 22.70.00.00 | B17: BERG SportsGoal S + Target Net | C17: 8715839105032 | D17: 132.67
A18: 22.70.01.00 | B18: BERG SportsGoal M + Target Net | C18: 8715839105049 | D18: 172.67
A19: 22.70.02.00 | B19: BERG SportsGoal L + Target Net | C19: 8715839105056 | D19: 232.67
B21: BERG AirTrack
A22: 36.01.14.01 | B22: BERG AirTrack Home 300 | C22: 8715839103489 | D22: 199.33333
A23: 36.01.24.01 | B23: BERG AirTrack Home 500 | C23: 8715839103496 | D23: 232.66667
A24: 36.02.24.01 | B24: BERG AirTrack Sport 500 | C24: 8715839103502 | D24: 366
B26: BERG Infinity Pods
A27: 35.82.01.00 | B27: BERG Infinity Pods - Set 3 | C27: 8715839090482 | D27: 86
A28: 35.82.02.00 | B28: BERG Infinity Pods - Set 6 | C28: 8715839090499 | D28: 166
A29: 35.82.03.00 | B29: BERG Infinity Pods - Single Pod | C29: 8715839090505 | D29: 39.333333
B32: Selective distrubution
B33: New product
A37: All product information and prices subject to change without notice
A38: General terms and conditions BERG Toys apply. These can be found at www.bergtoys.com. A copy can be supplied on request.
A39: WWW.DEALERZONE.NET

Sheet Pricelist Spareparts 2026
A1: Pricelist Spare parts
A2: Valid as per 1 January 2026
A4: Product number | B4: Product name EN-US | C4: EAN code | D4: EP
A5: 51.07.00.82 | B5: XL Frame - Steering rod secure spring (20x) | C5: 8715839066029 | D5: 8.46
A6: 51.07.00.83 | B6: XL Frame - U-bracket plastic for chair frame (10x) | C6: 8715839066111 | D6: 11.26
A7: 51.07.00.52 | B7: XL Frame - Plastic parts | C7: 8715839056884 | D7: 37.99
A8: 51.07.00.84 | B8: XXL Frame - Chain guard front part | C8: 8715839066036 | D8: 49.33
A9: 51.07.00.85 | B9: XXL Frame - Crank shaft with crank set 140, 36T + pedals | C9: 8715839066128 | D9: 86.67
A10: 51.08.00.00 | B10: E-Frame - Battery 10Ah/24V | C10: 8715839066135 | D10: 366
A11: 51.08.00.01 | B11: E-Frame - Charger 24V | C11: 8715839066142 | D11: 83.33
A12: 51.08.00.02 | B12: E-Frame - Central motor 24V/250W incl. crank set | C12: 8715839066159 | D12: 859.33
A13: 51.08.00.03 | B13: E-Frame - Battery connector | C13: 8715839066166 | D13: 93.33
A14: 51.08.00.04 | B14: E-Frame - Sensor and magnet (set) | C14: 8715839066173 | D14: 55.33
A15: 51.08.00.05 | B15: E-Frame - Display with bracing rod (296mm) | C15: 8715839066180 | D15: 130
A16: 51.08.00.06 | B16: E-Frame - Chain 136s + chain 44s | C16: 8715839066197 | D16: 45.33
... A1822: 51.75.00.70 | B1822: Biky - Sticker Set Cross Red Handbrake | C1822: 8715839105841 | D1822: 19.33

Sheet $13.000 Container
O1: Aangepaste prijs | Q1: Geel gemarkeerd prijzen nog niet 100% final
A2: Pagina 1/1 | E2: 2021 | J2: 2017 | N2: 2022 | W2: 2018 | Z2: $13.000 container price
E5: Dealerprijs | F5: Verkoopadviesprijs | N5: inkoopprijs | O5: verkoopprijs | P5: Verschil in kostprijs % | Q5: Nieuwe kostprijs RMB | R5: Nieuwe kostprijs € | S5: Verschil in prijs | T5: Bruto TF | U5: Diff | Z5: Totaal verhoging MRSP | AA5: Upcharge vrachtkosten | AB5: QTY per container | AC5: Container waarde | AD5: Benodigde upcharge | AE5: Resultaat
A6: Art. nr. | B6: Omschrijving | C6: EAN-code | E6: excl. Btw | F6: incl. Btw | G6: Kostp. RMB | H6: Kostprijs | I6: Bruto TF | N6: excl. BTW | O6: incl. BTW
E7: EP | F7: Consument | J7: EP USD | K7: EP Ireland | L7: EP UK | N7: EP | O7: Consument | S7: Consument | W7: EP USD | X7: EP Ireland | Y7: EP UK
B8: BERG GO
A9: 24.52.00.00 | B9: BERG GO Twirl Turquoise | C9: 8715839085334 | E9: NVT | F9: NVT | G9: NVT | H9: NVT | I9: NVT | N9: =O9/1.5 -> 56.666667 | O9: 85 | P9: NVT | Q9: 168 | R9: =Q9/7.6 -> 22.105263 | S9: NVT | T9: =N9/R9 -> 2.5634921 | U9: NVT | W9: 0 | X9: 0 | Y9: 0 | Z9: NVT | AA9: NVT | AB9: 1032 | AC9: =N9*AB9 -> 58480 | AD9: NVT | AE9: NVT
A10: 24.52.01.00 | B10: BERG GO Twirl Multicolor | C10: 8715839085341 | E10: NVT | F10: NVT | G10: NVT | H10: NVT | I10: NVT | N10: =O10/1.5 -> 56.666667 | O10: 85 | P10: NVT | Q10: 168 | R10: =Q10/7.6 -> 22.105263 | S10: NVT | T10: =N10/R10 -> 2.5634921 | U10: NVT | W10: 0 | X10: 0 | Y10: 0 | Z10: NVT | AA10: NVT | AB10: 1032 | AC10: =N10*AB10 -> 58480 | AD10: NVT | AE10: NVT
B11: BERG GO²
A12: 24.50.00.00 | B12: BERG GO² Blue | C12: 8715839065404 | E12: =F12/1.5 -> 59.333333 | F12: 89 | G12: 194.56 | H12: =G12/7.85 -> 24.784713 | I12: =E12/H12 -> 2.3939487 | J12: 0 | K12: 0 | L12: 0 | N12: =O12/1.5 -> 70 | O12: 105 | P12: =(Q12-G12)/(G12) -> 0.030016447 | Q12: 200.4 | R12: =Q12/7.6 -> 26.368421 | S12: =O12-F12 -> 16 | T12: =N12/R12 -> 2.6546906 | U12: =T12-I12 -> 0.26074188 | W12: 0 | X12: 0 | Y12: 0 | Z12: =S12/F12 -> 0.17977528 | AA12: =11200/AC12 -> 0.13559322 | AB12: 1180 | AC12: =N12*AB12 -> 82600 | AD12: =AA12+P12 -> 0.16560967 | AE12: =AD12-Z12 -> -0.014165613
A13: 24.50.01.00 | B13: BERG GO² Pink | C13: =VLOOKUP(A13,EAN!$A:$C,3,0) -> 8715839064322 | E13: =F13/1.5 -> 59.333333 | F13: 89 | G13: 194.56 | H13: =G13/7.85 -> 24.784713 | I13: =E13/H13 -> 2.3939487 | J13: 0 | K13: 0 | L13: 0 | N13: =O13/1.5 -> 70 | O13: 105 | P13: =(Q13-G13)/(G13) -> 0.030016447 | Q13: 200.4 | R13: =Q13/7.6 -> 26.368421 | S13: =O13-F13 -> 16 | T13: =N13/R13 -> 2.6546906 | U13: =T13-I13 -> 0.26074188 | W13: 0 | X13: 0 | Y13: 0 | Z13: =S13/F13 -> 0.17977528 | AA13: =11200/AC13 -> 0.13559322 | AB13: 1180 | AC13: =N13*AB13 -> 82600 | AD13: =AA13+P13 -> 0.16560967 | AE13: =AD13-Z13 -> -0.014165613
A14: 24.50.02.00 | B14: BERG GO² Mint | C14: =VLOOKUP(A14,EAN!$A:$C,3,0) -> 8715839064339 | E14: =F14/1.5 -> 59.333333 | F14: 89 | G14: 194.56 | H14: =G14/7.85 -> 24.784713 | I14: =E14/H14 -> 2.3939487 | J14: 0 | K14: 0 | L14: 0 | N14: =O14/1.5 -> 70 | O14: 105 | P14: =(Q14-G14)/(G14) -> 0.030016447 | Q14: 200.4 | R14: =Q14/7.6 -> 26.368421 | S14: =O14-F14 -> 16 | T14: =N14/R14 -> 2.6546906 | U14: =T14-I14 -> 0.26074188 | W14: 0 | X14: 0 | Y14: 0 | Z14: =S14/F14 -> 0.17977528 | AA14: =11200/AC14 -> 0.13559322 | AB14: 1180 | AC14: =N14*AB14 -> 82600 | AD14: =AA14+P14 -> 0.16560967 | AE14: =AD14-Z14 -> -0.014165613
A15: 24.50.03.00 | B15: BERG GO² SparX Red | C15: 8715839070453 | E15: =F15/1.5 -> 63.333333 | F15: 95 | G15: 201.19 | H15: =G15/7.85 -> 25.629299 | I15: =E15/H15 -> 2.4711301 | J15: 0 | K15: 0 | L15: 0 | N15: =O15/1.5 -> 76.666667 | O15: 115 | P15: =(Q15-G15)/(G15) -> 0.030021373 | Q15: 207.23 | R15: =Q15/7.6 -> 27.267105 | S15: =O15-F15 -> 20 | T15: =N15/R15 -> 2.8116907 | U15: =T15-I15 -> 0.3405606 | W15: 0 | X15: 0 | Y15: 0 | Z15: =S15/F15 -> 0.21052632 | AA15: =11200/AC15 -> 0.12380251 | AB15: 1180 | AC15: =N15*AB15 -> 90466.667 | AD15: =AA15+P15 -> 0.15382388 | AE15: =AD15-Z15 -> -0.056702437
A16: 24.50.04.00 | B16: BERG GO² SparX Yellow | C16: 8715839070460 | E16: =F16/1.5 -> 63.333333 | F16: 95 | G16: 199.6 | H16: =G16/7.85 -> 25.426752 | I16: =E16/H16 -> 2.490815 | J16: 0 | K16: 0 | L16: 0 | N16: =O16/1.5 -> 76.666667 | O16: 115 | P16: =(Q16-G16)/(G16) -> 0.03001002 | Q16: 205.59 | R16: =Q16/7.6 -> 27.051316 | S16: =O16-F16 -> 20 | T16: =N16/R16 -> 2.8341197 | U16: =T16-I16 -> 0.34330472 | W16: 0 | X16: 0 | Y16: 0 | Z16: =S16/F16 -> 0.21052632 | AA16: =11200/AC16 -> 0.12380251 | AB16: 1180 | AC16: =N16*AB16 -> 90466.667 | AD16: =AA16+P16 -> 0.15381253 | AE16: =AD16-Z16 -> -0.05671379
A17: 24.50.07.00 | B17: BERG GO² Retro Pink | C17: 8715839076028 | E17: =F17/1.5 -> 59.333333 | F17: 89 | G17: 199.07 | H17: =G17/7.85 -> 25.359236 | I17: =E17/H17 -> 2.339713 | N17: =O17/1.5 -> 70 | O17: 105 | P17: =(Q17-G17)/(G17) -> 0.029989451 | Q17: 205.04 | R17: =Q17/7.6 -> 26.978947 | S17: =O17-F17 -> 16 | T17: =N17/R17 -> 2.5946157 | U17: =T17-I17 -> 0.25490269 | Z17: =S17/F17 -> 0.17977528 | AA17: =11200/AC17 -> 0.15503876 | AB17: 1032 | AC17: =N17*AB17 -> 72240 | AD17: =AA17+P17 -> 0.18502821 | AE17: =AD17-Z17 -> 0.0052529297
A18: 24.50.08.00 | B18: BERG GO² Retro Green | C18: 8715839076035 | E18: =F18/1.5 -> 59.333333 | F18: 89 | G18: 199.07 | H18: =G18/7.85 -> 25.359236 | I18: =E18/H18 -> 2.339713 | N18: =O18/1.5 -> 70 | O18: 105 | P18: =(Q18-G18)/(G18) -> 0.029989451 | Q18: 205.04 | R18: =Q18/7.6 -> 26.978947 | S18: =O18-F18 -> 16 | T18: =N18/R18 -> 2.5946157 | U18: =T18-I18 -> 0.25490269 | Z18: =S18/F18 -> 0.17977528 | AA18: =11200/AC18 -> 0.15503876 | AB18: 1032 | AC18: =N18*AB18 -> 72240 | AD18: =AA18+P18 -> 0.18502821 | AE18: =AD18-Z18 -> 0.0052529297
B19: BERG Biky
A20: 24.75.10.00 | B20: BERG Biky Mini Green | C20: 8715839077735 | E20: =F20/1.5 -> 59.333333 | F20: 89 | G20: 187.9 | H20: =G20/7.85 -> 23.936306 | I20: =E20/H20 -> 2.4788008 | J20: =VLOOKUP(A20,Mastersheet!$A:$AK,30,0) -> #N/A | K20: =VLOOKUP(A20,Mastersheet!$A:$AK,32,0) -> #N/A | L20: =VLOOKUP(A20,Mastersheet!$A:$AK,34,0) -> #N/A | N20: =O20/1.5 -> 72.666667 | O20: 109 | P20: =(Q20-G20)/(G20) -> 0.11335817 | Q20: 209.2 | R20: =Q20/7.6 -> 27.526316 | S20: =O20-F20 -> 20 | T20: =N20/R20 -> 2.639898 | U20: =T20-I20 -> 0.16109724 | W20: 0 | X20: 0 | Y20: 0 | Z20: =S20/F20 -> 0.2247191 | AA20: =11200/AC20 -> 0.099437703 | AB20: 1550 | AC20: =N20*AB20 -> 112633.33 | AD20: =AA20+P20 -> 0.21279587 | AE20: =AD20-Z20 -> -0.011923228
A21: 24.75.11.00 | B21: BERG Biky Mini Red | C21: 8715839077742 | E21: =F21/1.5 -> 59.333333 | F21: 89 | G21: 187.9 | H21: =G21/7.85 -> 23.936306 | I21: =E21/H21 -> 2.4788008 | J21: =VLOOKUP(A21,Mastersheet!$A:$AK,30,0) -> #N/A | K21: =VLOOKUP(A21,Mastersheet!$A:$AK,32,0) -> #N/A | L21: =VLOOKUP(A21,Mastersheet!$A:$AK,34,0) -> #N/A | N21: =O21/1.5 -> 72.666667 | O21: 109 | P21: =(Q21-G21)/(G21) -> 0.11335817 | Q21: 209.2 | R21: =Q21/7.6 -> 27.526316 | S21: =O21-F21 -> 20 | T21: =N21/R21 -> 2.639898 | U21: =T21-I21 -> 0.16109724 | W21: 0 | X21: 0 | Y21: 0 | Z21: =S21/F21 -> 0.2247191 | AA21: =11200/AC21 -> 0.099437703 | AB21: 1550 | AC21: =N21*AB21 -> 112633.33 | AD21: =AA21+P21 -> 0.21279587 | AE21: =AD21-Z21 -> -0.011923228
A22: 24.75.30.00 | B22: BERG Biky City Green | C22: 8715839077759 | E22: =F22/1.5 -> 66 | F22: 99 | G22: 221.4 | H22: =G22/7.85 -> 28.203822 | I22: =E22/H22 -> 2.3401084 | J22: =VLOOKUP(A22,Mastersheet!$A:$AK,30,0) -> #N/A | K22: =VLOOKUP(A22,Mastersheet!$A:$AK,32,0) -> #N/A | L22: =VLOOKUP(A22,Mastersheet!$A:$AK,34,0) -> #N/A | N22: =O22/1.5 -> 79.333333 | O22: 119 | P22: =(Q22-G22)/(G22) -> 0.12059621 | Q22: 248.1 | R22: =Q22/7.6 -> 32.644737 | S22: =O22-F22 -> 20 | T22: =N22/R22 -> 2.4302029 | U22: =T22-I22 -> 0.090094474 | W22: 0 | X22: 0 | Y22: 0 | Z22: =S22/F22 -> 0.2020202 | AA22: =11200/AC22 -> 0.091081594 | AB22: 1550 | AC22: =N22*AB22 -> 122966.67 | AD22: =AA22+P22 -> 0.2116778 | AE22: =AD22-Z22 -> 0.0096575979
A23: 24.75.31.00 | B23: BERG Biky City Red | C23: 8715839077766 | E23: =F23/1.5 -> 66 | F23: 99 | G23: 221.4 | H23: =G23/7.85 -> 28.203822 | I23: =E23/H23 -> 2.3401084 | J23: =VLOOKUP(A23,Mastersheet!$A:$AK,30,0) -> #N/A | K23: =VLOOKUP(A23,Mastersheet!$A:$AK,32,0) -> #N/A | L23: =VLOOKUP(A23,Mastersheet!$A:$AK,34,0) -> #N/A | N23: =O23/1.5 -> 79.333333 | O23: 119 | P23: =(Q23-G23)/(G23) -> 0.12059621 | Q23: 248.1 | R23: =Q23/7.6 -> 32.644737 | S23: =O23-F23 -> 20 | T23: =N23/R23 -> 2.4302029 | U23: =T23-I23 -> 0.090094474 | W23: 0 | X23: 0 | Y23: 0 | Z23: =S23/F23 -> 0.2020202 | AA23: =11200/AC23 -> 0.091081594 | AB23: 1550 | AC23: =N23*AB23 -> 122966.67 | AD23: =AA23+P23 -> 0.2116778 | AE23: =AD23-Z23 -> 0.0096575979
A24: 24.75.50.00 | B24: BERG Biky Retro Green | C24: 8715839077773 | E24: =F24/1.5 -> 86 | F24: 129 | G24: 257.7 | H24: =G24/7.85 -> 32.828025 | I24: =E24/H24 -> 2.6197128 | J24: =VLOOKUP(A24,Mastersheet!$A:$AK,30,0) -> #N/A | K24: =VLOOKUP(A24,Mastersheet!$A:$AK,32,0) -> #N/A | L24: =VLOOKUP(A24,Mastersheet!$A:$AK,34,0) -> #N/A | N24: =O24/1.5 -> 103.33333 | O24: 155 | P24: =(Q24-G24)/(G24) -> 0.10865347 | Q24: 285.7 | R24: =Q24/7.6 -> 37.592105 | S24: =O24-F24 -> 26 | T24: =N24/R24 -> 2.7488041 | U24: =T24-I24 -> 0.12909126 | W24: 0 | X24: 0 | Y24: 0 | Z24: =S24/F24 -> 0.20155039 | AA24: =11200/AC24 -> 0.069927159 | AB24: 1550 | AC24: =N24*AB24 -> 160166.67 | AD24: =AA24+P24 -> 0.17858063 | AE24: =AD24-Z24 -> -0.022969755
A25: 24.75.51.00 | B25: BERG Biky Retro Pink | C25: 8715839077780 | E25: =F25/1.5 -> 86 | F25: 129 | G25: 257.7 | H25: =G25/7.85 -> 32.828025 | I25: =E25/H25 -> 2.6197128 | J25: =VLOOKUP(A25,Mastersheet!$A:$AK,30,0) -> #N/A | K25: =VLOOKUP(A25,Mastersheet!$A:$AK,32,0) -> #N/A | L25: =VLOOKUP(A25,Mastersheet!$A:$AK,34,0) -> #N/A | N25: =O25/1.5 -> 103.33333 | O25: 155 | P25: =(Q25-G25)/(G25) -> 0.10865347 | Q25: 285.7 | R25: =Q25/7.6 -> 37.592105 | S25: =O25-F25 -> 26 | T25: =N25/R25 -> 2.7488041 | U25: =T25-I25 -> 0.12909126 | W25: 0 | X25: 0 | Y25: 0 | Z25: =S25/F25 -> 0.20155039 | AA25: =11200/AC25 -> 0.069927159 | AB25: 1550 | AC25: =N25*AB25 -> 160166.67 | AD25: =AA25+P25 -> 0.17858063 | AE25: =AD25-Z25 -> -0.022969755
A26: 24.75.70.00 | B26: BERG Biky Cross Green | C26: 8715839077797 | E26: =F26/1.5 -> 79.333333 | F26: 119 | G26: 250.8 | H26: =G26/7.85 -> 31.949045 | I26: =E26/H26 -> 2.4831207 | N26: =O26/1.5 -> 96.666667 | O26: 145 | P26: =(Q26-G26)/(G26) -> 0.14354067 | Q26: 286.8 | R26: =Q26/7.6 -> 37.736842 | S26: =O26-F26 -> 26 | T26: =N26/R26 -> 2.5615993 | U26: =T26-I26 -> 0.078478576 | Z26: =S26/F26 -> 0.21848739 | AA26: =11200/AC26 -> 0.074749722 | AB26: 1550 | AC26: =N26*AB26 -> 149833.33 | AD26: =AA26+P26 -> 0.21829039 | AE26: =AD26-Z26 -> -0.00019700319
A27: 24.75.71.00 | B27: BERG Biky Cross Red | C27: 8715839077803 | E27: =F27/1.5 -> 79.333333 | F27: 119 | G27: 250.8 | H27: =G27/7.85 -> 31.949045 | I27: =E27/H27 -> 2.4831207 | N27: =O27/1.5 -> 96.666667 | O27: 145 | P27: =(Q27-G27)/(G27) -> 0.14354067 | Q27: 286.8 | R27: =Q27/7.6 -> 37.736842 | S27: =O27-F27 -> 26 | T27: =N27/R27 -> 2.5615993 | U27: =T27-I27 -> 0.078478576 | Z27: =S27/F27 -> 0.21848739 | AA27: =11200/AC27 -> 0.074749722 | AB27: 1550 | AC27: =N27*AB27 -> 149833.33 | AD27: =AA27+P27 -> 0.21829039 | AE27: =AD27-Z27 -> -0.00019700319
A28: 24.75.72.00 | B28: BERG Biky Cross Grey | C28: 8715839077810 | E28: =F28/1.5 -> 79.333333 | F28: 119 | G28: 250.8 | H28: =G28/7.85 -> 31.949045 | I28: =E28/H28 -> 2.4831207 | J28: =VLOOKUP(A28,Mastersheet!$A:$AK,30,0) -> #N/A | K28: =VLOOKUP(A28,Mastersheet!$A:$AK,32,0) -> #N/A | L28: =VLOOKUP(A28,Mastersheet!$A:$AK,34,0) -> #N/A | N28: =O28/1.5 -> 96.666667 | O28: 145 | P28: =(Q28-G28)/(G28) -> 0.14354067 | Q28: 286.8 | R28: =Q28/7.6 -> 37.736842 | S28: =O28-F28 -> 26 | T28: =N28/R28 -> 2.5615993 | U28: =T28-I28 -> 0.078478576 | W28: 0 | X28: 0 | Y28: 0 | Z28: =S28/F28 -> 0.21848739 | AA28: =11200/AC28 -> 0.074749722 | AB28: 1550 | AC28: =N28*AB28 -> 149833.33 | AD28: =AA28+P28 -> 0.21829039 | AE28: =AD28-Z28 -> -0.00019700319
A29: 24.74.30.00 | B29: BERG Biky City Blue Handbrake | C29: 8715839085372 | E29: NVT | F29: NVT | G29: NVT | H29: NVT | I29: NVT | N29: =O29/1.5 -> 86 | O29: 129 | P29: NVT | Q29: =Q23+30 -> 278.1 | R29: =Q29/7.6 -> 36.592105 | S29: NVT | T29: =N29/R29 -> 2.3502337 | U29: NVT | Z29: NVT | AA29: NVT | AB29: 1550 | AC29: =N29*AB29 -> 133300 | AD29: NVT | AE29: NVT
A30: 24.74.70.00 | B30: BERG Biky Cross Blue Handbrake | C30: 8715839085358 | E30: NVT | F30: NVT | G30: NVT | H30: NVT | I30: NVT | N30: =O30/1.5 -> 103.33333 | O30: 155 | P30: NVT | Q30: =Q28+25 -> 311.8 | R30: =Q30/7.6 -> 41.026316 | S30: NVT | T30: =N30/R30 -> 2.5187086 | U30: NVT | Z30: NVT | AA30: NVT | AB30: 1550 | AC30: =N30*AB30 -> 160166.67 | AD30: NVT | AE30: NVT
A31: 24.74.71.00 | B31: BERG Biky Cross Grey Handbrake | C31: 8715839085365 | E31: NVT | F31: NVT | G31: NVT | H31: NVT | I31: NVT | N31: =O31/1.5 -> 103.33333 | O31: 155 | P31: NVT | Q31: =Q28+30 -> 316.8 | R31: =Q31/7.6 -> 41.684211 | S31: NVT | T31: =N31/R31 -> 2.4789562 | U31: NVT | Z31: NVT | AA31: NVT | AB31: 1550 | AC31: =N31*AB31 -> 160166.67 | AD31: NVT | AE31: NVT
B32: BERG BeachWagon
A33: 18.07.10.01 | B33: BERG Beach Wagon L | C33: 8715839045222 | E33: =F33/1.5 -> 159.33333 | F33: 239 | H33: =35.74+37 -> 72.74 | I33: =E33/H33 -> 2.19045 | J33: =VLOOKUP(A33,Mastersheet!$A:$AK,30,0) -> 183.2 | K33: =VLOOKUP(A33,Mastersheet!$A:$AK,32,0) -> 151.83 | L33: =VLOOKUP(A33,Mastersheet!$A:$AK,34,0) -> 121.92 | N33: =O33/1.5 -> 190 | O33: 285 | P33: =(R33-H33)/(H33) -> 0.11850426 | R33: =40.36+41 -> 81.36 | S33: =O33-F33 -> 46 | T33: =N33/R33 -> 2.3352999 | U33: =T33-I33 -> 0.1448499 | W33: 0 | X33: 0 | Y33: 0 | Z33: =S33/F33 -> 0.19246862 | AA33: =11200/AC33 -> 0.03803056 | AB33: 1550 | AC33: =N33*AB33 -> 294500
A34: 18.07.17.01 | B34: BERG Beach Wagon XL | C34: 8715839045208 | E34: =F34/1.5 -> 179.33333 | F34: 269 | H34: =35.74+47 -> 82.74 | I34: =E34/H34 -> 2.1674321 | J34: =VLOOKUP(A34,Mastersheet!$A:$AK,30,0) -> 207.2 | K34: =VLOOKUP(A34,Mastersheet!$A:$AK,32,0) -> 170.12 | L34: =VLOOKUP(A34,Mastersheet!$A:$AK,34,0) -> 139.42 | N34: =O34/1.5 -> 216.66667 | O34: 325 | P34: =(R34-H34)/(H34) -> 0.11626783 | R34: =40.36+52 -> 92.36 | S34: =O34-F34 -> 56 | T34: =N34/R34 -> 2.3458929 | U34: =T34-I34 -> 0.17846077 | W34: 0 | X34: 0 | Y34: 0 | Z34: =S34/F34 -> 0.20817844 | AA34: =11200/AC34 -> 0.033349876 | AB34: 1550 | AC34: =N34*AB34 -> 335833.33
B35: BERG Accessoires
A36: 16.00.01.00 | B36: BERG Carrying Strap | C36: 8715839065749 | E36: =F36/1.5 -> 6.6666667 | F36: 10 | G36: 18 | H36: =G36/7.85 -> 2.2929936 | I36: =E36/H36 -> 2.9074074 | J36: =VLOOKUP(A36,Mastersheet!$A:$AK,30,0) -> #N/A | K36: =VLOOKUP(A36,Mastersheet!$A:$AK,32,0) -> #N/A | L36: =VLOOKUP(A36,Mastersheet!$A:$AK,34,0) -> #N/A | N36: =O36/1.5 -> 9.3333333 | O36: 14 | P36: =(Q36-G36)/(G36) -> 0 | Q36: 18 | R36: =Q36/7.6 -> 2.3684211 | S36: =O36-F36 -> 4 | T36: =N36/R36 -> 3.9407407 | U36: =T36-I36 -> 1.0333333 | W36: 0 | X36: 0 | Y36: 0 | Z36: =S36/F36 -> 0.4 | AA36: =11200/AC36 -> 0.77419355 | AB36: 1550 | AC36: =N36*AB36 -> 14466.667
A37: 16.50.00.00 | B37: BERG Push Handle XS | C37: 8715839065725 | E37: =F37/1.5 -> 16.666667 | F37: 25 | G37: 50 | H37: =G37/7.85 -> 6.3694268 | I37: =E37/H37 -> 2.6166667 | J37: =VLOOKUP(A37,Mastersheet!$A:$AK,30,0) -> #N/A | K37: =VLOOKUP(A37,Mastersheet!$A:$AK,32,0) -> #N/A | L37: =VLOOKUP(A37,Mastersheet!$A:$AK,34,0) -> #N/A | N37: =O37/1.5 -> 19.333333 | O37: 29 | P37: =(Q37-G37)/(G37) -> 0.1 | Q37: 55 | R37: =Q37/7.6 -> 7.2368421 | S37: =O37-F37 -> 4 | T37: =N37/R37 -> 2.6715152 | U37: =T37-I37 -> 0.054848485 | W37: 0 | X37: 0 | Y37: 0 | Z37: =S37/F37 -> 0.16 | AA37: =11200/AC37 -> 0.37374861 | AB37: 1550 | AC37: =N37*AB37 -> 29966.667
A38: 16.00.00.00 | B38: BERG Safety Flag XS | C38: 8715839065732 | E38: =F38/1.5 -> 8.3333333 | F38: 12.5 | G38: 17.6 | H38: =G38/7.85 -> 2.2420382 | I38: =E38/H38 -> 3.7168561 | J38: =VLOOKUP(A38,Mastersheet!$A:$AK,30,0) -> #N/A | K38: =VLOOKUP(A38,Mastersheet!$A:$AK,32,0) -> #N/A | L38: =VLOOKUP(A38,Mastersheet!$A:$AK,34,0) -> #N/A | N38: =O38/1.5 -> 10.666667 | O38: 16 | P38: =(Q38-G38)/(G38) -> 0.1 | Q38: 19.36 | R38: =Q38/7.6 -> 2.5473684 | S38: =O38-F38 -> 3.5 | T38: =N38/R38 -> 4.1873278 | U38: =T38-I38 -> 0.47047176 | W38: 0 | X38: 0 | Y38: 0 | Z38: =S38/F38 -> 0.28 | AA38: =11200/AC38 -> 0.67741935 | AB38: 1550 | AC38: =N38*AB38 -> 16533.333
A39: 16.00.04.00 | B39: BERG Helmet S | C39: 8715839078909 | E39: =F39/1.5 -> 12.666667 | F39: 19 | G39: 45 | H39: =G39/7.85 -> 5.7324841 | I39: =E39/H39 -> 2.2096296 | N39: =O39/1.5 -> 18.333333 | O39: 27.5 | P39: =(Q39-G39)/(G39) -> 0 | Q39: 45 | R39: =Q39/7.6 -> 5.9210526 | S39: =O39-F39 -> 8.5 | T39: =N39/R39 -> 3.0962963 | U39: =T39-I39 -> 0.88666667 | Z39: =S39/F39 -> 0.44736842 | AA39: =11200/AC39 -> 0.3941349 | AB39: 1550 | AC39: =N39*AB39 -> 28416.667
A40: 16.00.05.00 | B40: BERG Biky Protection Cushion | C40: 8715839078916 | E40: =F40/1.5 -> 3.3333333 | F40: 5 | G40: 7.4 | H40: =G40/7.85 -> 0.94267516 | I40: =E40/H40 -> 3.536036 | N40: =O40/1.5 -> 7.3333333 | O40: 11 | P40: =(Q40-G40)/(G40) -> 0.13513514 | Q40: 8.4 | R40: =Q40/7.6 -> 1.1052632 | S40: =O40-F40 -> 6 | T40: =N40/R40 -> 6.6349206 | U40: =T40-I40 -> 3.0988846 | Z40: =S40/F40 -> 1.2 | AA40: =11200/AC40 -> 0.98533724 | AB40: 1550 | AC40: =N40*AB40 -> 11366.667
A41: 16.00.06.00 | B41: BERG Biky Kickstand | C41: 8715839078923 | E41: =F41/1.5 -> 8.3333333 | F41: 12.5 | G41: 24.5 | H41: =G41/7.85 -> 3.1210191 | I41: =E41/H41 -> 2.670068 | N41: =O41/1.5 -> 10.666667 | O41: 16 | P41: =(Q41-G41)/(G41) -> 0 | Q41: 24.5 | R41: =Q41/7.6 -> 3.2236842 | S41: =O41-F41 -> 3.5 | T41: =N41/R41 -> 3.3088435 | U41: =T41-I41 -> 0.63877551 | Z41: =S41/F41 -> 0.28 | AA41: =11200/AC41 -> 0.67741935 | AB41: 1550 | AC41: =N41*AB41 -> 16533.333
A42: 16.00.07.00 | B42: BERG Biky Safety Flag | C42: 8715839078930 | E42: =F42/1.5 -> 8.3333333 | F42: 12.5 | G42: 20 | H42: =G42/7.85 -> 2.5477707 | I42: =E42/H42 -> 3.2708333 | N42: =O42/1.5 -> 10.666667 | O42: 16 | P42: =(Q42-G42)/(G42) -> 0.1 | Q42: 22 | R42: =Q42/7.6 -> 2.8947368 | S42: =O42-F42 -> 3.5 | T42: =N42/R42 -> 3.6848485 | U42: =T42-I42 -> 0.41401515 | Z42: =S42/F42 -> 0.28 | AA42: =11200/AC42 -> 0.67741935 | AB42: 1550 | AC42: =N42*AB42 -> 16533.333
...

Sheet $15.000 Container
O1: Aangepaste prijs | Q1: Geel gemarkeerd prijzen nog niet 100% final
A2: Pagina 1/1 | E2: 2021 | J2: 2017 | N2: 2022 | W2: 2018 | Z2: $15.000 container price
E5: Dealerprijs | F5: Verkoopadviesprijs | N5: inkoopprijs | O5: verkoopprijs | P5: Verschil in kostprijs % | Q5: Nieuwe kostprijs RMB | R5: Nieuwe kostprijs € | S5: Verschil in prijs | T5: Bruto TF | U5: Diff | Z5: Totaal verhoging MRSP | AA5: Upcharge vrachtkosten | AB5: QTY per container | AC5: Container waarde | AD5: Benodigde upcharge | AE5: Resultaat
A6: Art. nr. | B6: Omschrijving | C6: EAN-code | E6: excl. Btw | F6: incl. Btw | G6: Kostp. RMB | H6: Kostprijs | I6: Bruto TF | N6: excl. BTW | O6: incl. BTW
E7: EP | F7: Consument | J7: EP USD | K7: EP Ireland | L7: EP UK | N7: EP | O7: Consument | S7: Consument | W7: EP USD | X7: EP Ireland | Y7: EP UK
B8: BERG GO
A9: 24.52.00.00 | B9: BERG GO Twirl Turquoise | C9: 8715839085334 | E9: NVT | F9: NVT | G9: NVT | H9: NVT | I9: NVT | N9: =O9/1.5 -> 56.666667 | O9: 85 | P9: NVT | Q9: 168 | R9: =Q9/7.6 -> 22.105263 | S9: NVT | T9: =N9/R9 -> 2.5634921 | U9: NVT | W9: 0 | X9: 0 | Y9: 0 | Z9: NVT | AA9: NVT | AB9: 1032 | AC9: =N9*AB9 -> 58480 | AD9: NVT | AE9: NVT
A10: 24.52.01.00 | B10: BERG GO Twirl Multicolor | C10: 8715839085341 | E10: NVT | F10: NVT | G10: NVT | H10: NVT | I10: NVT | N10: =O10/1.5 -> 56.666667 | O10: 85 | P10: NVT | Q10: 168 | R10: =Q10/7.6 -> 22.105263 | S10: NVT | T10: =N10/R10 -> 2.5634921 | U10: NVT | W10: 0 | X10: 0 | Y10: 0 | Z10: NVT | AA10: NVT | AB10: 1032 | AC10: =N10*AB10 -> 58480 | AD10: NVT | AE10: NVT
B11: BERG GO²
A12: 24.50.00.00 | B12: BERG GO² Blue | C12: 8715839065404 | E12: =F12/1.5 -> 59.333333 | F12: 89 | G12: 194.56 | H12: =G12/7.85 -> 24.784713 | I12: =E12/H12 -> 2.3939487 | J12: 0 | K12: 0 | L12: 0 | N12: =O12/1.5 -> 70 | O12: 105 | P12: =(Q12-G12)/(G12) -> 0.030016447 | Q12: 200.4 | R12: =Q12/7.6 -> 26.368421 | S12: =O12-F12 -> 16 | T12: =N12/R12 -> 2.6546906 | U12: =T12-I12 -> 0.26074188 | W12: 0 | X12: 0 | Y12: 0 | Z12: =S12/F12 -> 0.17977528 | AA12: =13000/AC12 -> 0.15738499 | AB12: 1180 | AC12: =N12*AB12 -> 82600 | AD12: =AA12+P12 -> 0.18740144 | AE12: =AD12-Z12 -> 0.0076261544
A13: 24.50.01.00 | B13: BERG GO² Pink | C13: =VLOOKUP(A13,EAN!$A:$C,3,0) -> 8715839064322 | E13: =F13/1.5 -> 59.333333 | F13: 89 | G13: 194.56 | H13: =G13/7.85 -> 24.784713 | I13: =E13/H13 -> 2.3939487 | J13: 0 | K13: 0 | L13: 0 | N13: =O13/1.5 -> 70 | O13: 105 | P13: =(Q13-G13)/(G13) -> 0.030016447 | Q13: 200.4 | R13: =Q13/7.6 -> 26.368421 | S13: =O13-F13 -> 16 | T13: =N13/R13 -> 2.6546906 | U13: =T13-I13 -> 0.26074188 | W13: 0 | X13: 0 | Y13: 0 | Z13: =S13/F13 -> 0.17977528 | AA13: =13000/AC13 -> 0.15738499 | AB13: 1180 | AC13: =N13*AB13 -> 82600 | AD13: =AA13+P13 -> 0.18740144 | AE13: =AD13-Z13 -> 0.0076261544
A14: 24.50.02.00 | B14: BERG GO² Mint | C14: =VLOOKUP(A14,EAN!$A:$C,3,0) -> 8715839064339 | E14: =F14/1.5 -> 59.333333 | F14: 89 | G14: 194.56 | H14: =G14/7.85 -> 24.784713 | I14: =E14/H14 -> 2.3939487 | J14: 0 | K14: 0 | L14: 0 | N14: =O14/1.5 -> 70 | O14: 105 | P14: =(Q14-G14)/(G14) -> 0.030016447 | Q14: 200.4 | R14: =Q14/7.6 -> 26.368421 | S14: =O14-F14 -> 16 | T14: =N14/R14 -> 2.6546906 | U14: =T14-I14 -> 0.26074188 | W14: 0 | X14: 0 | Y14: 0 | Z14: =S14/F14 -> 0.17977528 | AA14: =13000/AC14 -> 0.15738499 | AB14: 1180 | AC14: =N14*AB14 -> 82600 | AD14: =AA14+P14 -> 0.18740144 | AE14: =AD14-Z14 -> 0.0076261544
A15: 24.50.03.00 | B15: BERG GO² SparX Red | C15: 8715839070453 | E15: =F15/1.5 -> 63.333333 | F15: 95 | G15: 201.19 | H15: =G15/7.85 -> 25.629299 | I15: =E15/H15 -> 2.4711301 | J15: 0 | K15: 0 | L15: 0 | N15: =O15/1.5 -> 76.666667 | O15: 115 | P15: =(Q15-G15)/(G15) -> 0.030021373 | Q15: 207.23 | R15: =Q15/7.6 -> 27.267105 | S15: =O15-F15 -> 20 | T15: =N15/R15 -> 2.8116907 | U15: =T15-I15 -> 0.3405606 | W15: 0 | X15: 0 | Y15: 0 | Z15: =S15/F15 -> 0.21052632 | AA15: =13000/AC15 -> 0.14369934 | AB15: 1180 | AC15: =N15*AB15 -> 90466.667 | AD15: =AA15+P15 -> 0.17372071 | AE15: =AD15-Z15 -> -0.036805606
A16: 24.50.04.00 | B16: BERG GO² SparX Yellow | C16: 8715839070460 | E16: =F16/1.5 -> 63.333333 | F16: 95 | G16: 199.6 | H16: =G16/7.85 -> 25.426752 | I16: =E16/H16 -> 2.490815 | J16: 0 | K16: 0 | L16: 0 | N16: =O16/1.5 -> 76.666667 | O16: 115 | P16: =(Q16-G16)/(G16) -> 0.03001002 | Q16: 205.59 | R16: =Q16/7.6 -> 27.051316 | S16: =O16-F16 -> 20 | T16: =N16/R16 -> 2.8341197 | U16: =T16-I16 -> 0.34330472 | W16: 0 | X16: 0 | Y16: 0 | Z16: =S16/F16 -> 0.21052632 | AA16: =13000/AC16 -> 0.14369934 | AB16: 1180 | AC16: =N16*AB16 -> 90466.667 | AD16: =AA16+P16 -> 0.17370936 | AE16: =AD16-Z16 -> -0.036816959
A17: 24.50.07.00 | B17: BERG GO² Retro Pink | C17: 8715839076028 | E17: =F17/1.5 -> 59.333333 | F17: 89 | G17: 199.07 | H17: =G17/7.85 -> 25.359236 | I17: =E17/H17 -> 2.339713 | N17: =O17/1.5 -> 72.666667 | O17: 109 | P17: =(Q17-G17)/(G17) -> 0.029989451 | Q17: 205.04 | R17: =Q17/7.6 -> 26.978947 | S17: =O17-F17 -> 20 | T17: =N17/R17 -> 2.6934582 | U17: =T17-I17 -> 0.35374519 | Z17: =S17/F17 -> 0.2247191 | AA17: =13000/AC17 -> 0.17335182 | AB17: 1032 | AC17: =N17*AB17 -> 74992 | AD17: =AA17+P17 -> 0.20334128 | AE17: =AD17-Z17 -> -0.021377826
A18: 24.50.08.00 | B18: BERG GO² Retro Green | C18: 8715839076035 | E18: =F18/1.5 -> 59.333333 | F18: 89 | G18: 199.07 | H18: =G18/7.85 -> 25.359236 | I18: =E18/H18 -> 2.339713 | N18: =O18/1.5 -> 72.666667 | O18: 109 | P18: =(Q18-G18)/(G18) -> 0.029989451 | Q18: 205.04 | R18: =Q18/7.6 -> 26.978947 | S18: =O18-F18 -> 20 | T18: =N18/R18 -> 2.6934582 | U18: =T18-I18 -> 0.35374519 | Z18: =S18/F18 -> 0.2247191 | AA18: =13000/AC18 -> 0.17335182 | AB18: 1032 | AC18: =N18*AB18 -> 74992 | AD18: =AA18+P18 -> 0.20334128 | AE18: =AD18-Z18 -> -0.021377826
B19: BERG Biky
A20: 24.75.10.00 | B20: BERG Biky Mini Green | C20: 8715839077735 | E20: =F20/1.5 -> 59.333333 | F20: 89 | G20: 187.9 | H20: =G20/7.85 -> 23.936306 | I20: =E20/H20 -> 2.4788008 | J20: =VLOOKUP(A20,Mastersheet!$A:$AK,30,0) -> #N/A | K20: =VLOOKUP(A20,Mastersheet!$A:$AK,32,0) -> #N/A | L20: =VLOOKUP(A20,Mastersheet!$A:$AK,34,0) -> #N/A | N20: =O20/1.5 -> 76.666667 | O20: 115 | P20: =(Q20-G20)/(G20) -> 0.11335817 | Q20: 209.2 | R20: =Q20/7.6 -> 27.526316 | S20: =O20-F20 -> 26 | T20: =N20/R20 -> 2.7852135 | U20: =T20-I20 -> 0.30641273 | W20: 0 | X20: 0 | Y20: 0 | Z20: =S20/F20 -> 0.29213483 | AA20: =13000/AC20 -> 0.10939691 | AB20: 1550 | AC20: =N20*AB20 -> 118833.33 | AD20: =AA20+P20 -> 0.22275508 | AE20: =AD20-Z20 -> -0.069379748
A21: 24.75.11.00 | B21: BERG Biky Mini Red | C21: 8715839077742 | E21: =F21/1.5 -> 59.333333 | F21: 89 | G21: 187.9 | H21: =G21/7.85 -> 23.936306 | I21: =E21/H21 -> 2.4788008 | J21: =VLOOKUP(A21,Mastersheet!$A:$AK,30,0) -> #N/A | K21: =VLOOKUP(A21,Mastersheet!$A:$AK,32,0) -> #N/A | L21: =VLOOKUP(A21,Mastersheet!$A:$AK,34,0) -> #N/A | N21: =O21/1.5 -> 76.666667 | O21: 115 | P21: =(Q21-G21)/(G21) -> 0.11335817 | Q21: 209.2 | R21: =Q21/7.6 -> 27.526316 | S21: =O21-F21 -> 26 | T21: =N21/R21 -> 2.7852135 | U21: =T21-I21 -> 0.30641273 | W21: 0 | X21: 0 | Y21: 0 | Z21: =S21/F21 -> 0.29213483 | AA21: =13000/AC21 -> 0.10939691 | AB21: 1550 | AC21: =N21*AB21 -> 118833.33 | AD21: =AA21+P21 -> 0.22275508 | AE21: =AD21-Z21 -> -0.069379748
A22: 24.75.30.00 | B22: BERG Biky City Green | C22: 8715839077759 | E22: =F22/1.5 -> 66 | F22: 99 | G22: 221.4 | H22: =G22/7.85 -> 28.203822 | I22: =E22/H22 -> 2.3401084 | J22: =VLOOKUP(A22,Mastersheet!$A:$AK,30,0) -> #N/A | K22: =VLOOKUP(A22,Mastersheet!$A:$AK,32,0) -> #N/A | L22: =VLOOKUP(A22,Mastersheet!$A:$AK,34,0) -> #N/A | N22: =O22/1.5 -> 83.333333 | O22: 125 | P22: =(Q22-G22)/(G22) -> 0.12059621 | Q22: 248.1 | R22: =Q22/7.6 -> 32.644737 | S22: =O22-F22 -> 26 | T22: =N22/R22 -> 2.5527341 | U22: =T22-I22 -> 0.21262571 | W22: 0 | X22: 0 | Y22: 0 | Z22: =S22/F22 -> 0.26262626 | AA22: =13000/AC22 -> 0.10064516 | AB22: 1550 | AC22: =N22*AB22 -> 129166.67 | AD22: =AA22+P22 -> 0.22124137 | AE22: =AD22-Z22 -> -0.041384895
A23: 24.75.31.00 | B23: BERG Biky City Red | C23: 8715839077766 | E23: =F23/1.5 -> 66 | F23: 99 | G23: 221.4 | H23: =G23/7.85 -> 28.203822 | I23: =E23/H23 -> 2.3401084 | J23: =VLOOKUP(A23,Mastersheet!$A:$AK,30,0) -> #N/A | K23: =VLOOKUP(A23,Mastersheet!$A:$AK,32,0) -> #N/A | L23: =VLOOKUP(A23,Mastersheet!$A:$AK,34,0) -> #N/A | N23: =O23/1.5 -> 83.333333 | O23: 125 | P23: =(Q23-G23)/(G23) -> 0.12059621 | Q23: 248.1 | R23: =Q23/7.6 -> 32.644737 | S23: =O23-F23 -> 26 | T23: =N23/R23 -> 2.5527341 | U23: =T23-I23 -> 0.21262571 | W23: 0 | X23: 0 | Y23: 0 | Z23: =S23/F23 -> 0.26262626 | AA23: =13000/AC23 -> 0.10064516 | AB23: 1550 | AC23: =N23*AB23 -> 129166.67 | AD23: =AA23+P23 -> 0.22124137 | AE23: =AD23-Z23 -> -0.041384895
A24: 24.75.50.00 | B24: BERG Biky Retro Green | C24: 8715839077773 | E24: =F24/1.5 -> 86 | F24: 129 | G24: 257.7 | H24: =G24/7.85 -> 32.828025 | I24: =E24/H24 -> 2.6197128 | J24: =VLOOKUP(A24,Mastersheet!$A:$AK,30,0) -> #N/A | K24: =VLOOKUP(A24,Mastersheet!$A:$AK,32,0) -> #N/A | L24: =VLOOKUP(A24,Mastersheet!$A:$AK,34,0) -> #N/A | N24: =O24/1.5 -> 103.33333 | O24: 155 | P24: =(Q24-G24)/(G24) -> 0.10865347 | Q24: 285.7 | R24: =Q24/7.6 -> 37.592105 | S24: =O24-F24 -> 26 | T24: =N24/R24 -> 2.7488041 | U24: =T24-I24 -> 0.12909126 | W24: 0 | X24: 0 | Y24: 0 | Z24: =S24/F24 -> 0.20155039 | AA24: =13000/AC24 -> 0.081165453 | AB24: 1550 | AC24: =N24*AB24 -> 160166.67 | AD24: =AA24+P24 -> 0.18981893 | AE24: =AD24-Z24 -> -0.011731462
A25: 24.75.51.00 | B25: BERG Biky Retro Pink | C25: 8715839077780 | E25: =F25/1.5 -> 86 | F25: 129 | G25: 257.7 | H25: =G25/7.85 -> 32.828025 | I25: =E25/H25 -> 2.6197128 | J25: =VLOOKUP(A25,Mastersheet!$A:$AK,30,0) -> #N/A | K25: =VLOOKUP(A25,Mastersheet!$A:$AK,32,0) -> #N/A | L25: =VLOOKUP(A25,Mastersheet!$A:$AK,34,0) -> #N/A | N25: =O25/1.5 -> 103.33333 | O25: 155 | P25: =(Q25-G25)/(G25) -> 0.10865347 | Q25: 285.7 | R25: =Q25/7.6 -> 37.592105 | S25: =O25-F25 -> 26 | T25: =N25/R25 -> 2.7488041 | U25: =T25-I25 -> 0.12909126 | W25: 0 | X25: 0 | Y25: 0 | Z25: =S25/F25 -> 0.20155039 | AA25: =13000/AC25 -> 0.081165453 | AB25: 1550 | AC25: =N25*AB25 -> 160166.67 | AD25: =AA25+P25 -> 0.18981893 | AE25: =AD25-Z25 -> -0.011731462
A26: 24.75.70.00 | B26: BERG Biky Cross Green | C26: 8715839077797 | E26: =F26/1.5 -> 79.333333 | F26: 119 | G26: 250.8 | H26: =G26/7.85 -> 31.949045 | I26: =E26/H26 -> 2.4831207 | N26: =O26/1.5 -> 96.666667 | O26: 145 | P26: =(Q26-G26)/(G26) -> 0.14354067 | Q26: 286.8 | R26: =Q26/7.6 -> 37.736842 | S26: =O26-F26 -> 26 | T26: =N26/R26 -> 2.5615993 | U26: =T26-I26 -> 0.078478576 | Z26: =S26/F26 -> 0.21848739 | AA26: =13000/AC26 -> 0.08676307 | AB26: 1550 | AC26: =N26*AB26 -> 149833.33 | AD26: =AA26+P26 -> 0.23030374 | AE26: =AD26-Z26 -> 0.011816345
A27: 24.75.71.00 | B27: BERG Biky Cross Red | C27: 8715839077803 | E27: =F27/1.5 -> 79.333333 | F27: 119 | G27: 250.8 | H27: =G27/7.85 -> 31.949045 | I27: =E27/H27 -> 2.4831207 | N27: =O27/1.5 -> 96.666667 | O27: 145 | P27: =(Q27-G27)/(G27) -> 0.14354067 | Q27: 286.8 | R27: =Q27/7.6 -> 37.736842 | S27: =O27-F27 -> 26 | T27: =N27/R27 -> 2.5615993 | U27: =T27-I27 -> 0.078478576 | Z27: =S27/F27 -> 0.21848739 | AA27: =13000/AC27 -> 0.08676307 | AB27: 1550 | AC27: =N27*AB27 -> 149833.33 | AD27: =AA27+P27 -> 0.23030374 | AE27: =AD27-Z27 -> 0.011816345
A28: 24.75.72.00 | B28: BERG Biky Cross Grey | C28: 8715839077810 | E28: =F28/1.5 -> 79.333333 | F28: 119 | G28: 250.8 | H28: =G28/7.85 -> 31.949045 | I28: =E28/H28 -> 2.4831207 | J28: =VLOOKUP(A28,Mastersheet!$A:$AK,30,0) -> #N/A | K28: =VLOOKUP(A28,Mastersheet!$A:$AK,32,0) -> #N/A | L28: =VLOOKUP(A28,Mastersheet!$A:$AK,34,0) -> #N/A | N28: =O28/1.5 -> 96.666667 | O28: 145 | P28: =(Q28-G28)/(G28) -> 0.14354067 | Q28: 286.8 | R28: =Q28/7.6 -> 37.736842 | S28: =O28-F28 -> 26 | T28: =N28/R28 -> 2.5615993 | U28: =T28-I28 -> 0.078478576 | W28: 0 | X28: 0 | Y28: 0 | Z28: =S28/F28 -> 0.21848739 | AA28: =13000/AC28 -> 0.08676307 | AB28: 1550 | AC28: =N28*AB28 -> 149833.33 | AD28: =AA28+P28 -> 0.23030374 | AE28: =AD28-Z28 -> 0.011816345
A29: 24.74.30.00 | B29: BERG Biky City Blue Handbrake | C29: 8715839085372 | E29: NVT | F29: NVT | G29: NVT | H29: NVT | I29: NVT | N29: =O29/1.5 -> 90 | O29: 135 | P29: NVT | Q29: =Q23+30 -> 278.1 | R29: =Q29/7.6 -> 36.592105 | S29: NVT | T29: =N29/R29 -> 2.4595469 | U29: NVT | Z29: NVT | AA29: NVT | AB29: 1550 | AC29: =N29*AB29 -> 139500 | AD29: NVT | AE29: NVT
A30: 24.74.70.00 | B30: BERG Biky Cross Blue Handbrake | C30: 8715839085358 | E30: NVT | F30: NVT | G30: NVT | H30: NVT | I30: NVT | N30: =O30/1.5 -> 103.33333 | O30: 155 | P30: NVT | Q30: =Q28+25 -> 311.8 | R30: =Q30/7.6 -> 41.026316 | S30: NVT | T30: =N30/R30 -> 2.5187086 | U30: NVT | Z30: NVT | AA30: NVT | AB30: 1550 | AC30: =N30*AB30 -> 160166.67 | AD30: NVT | AE30: NVT
A31: 24.74.71.00 | B31: BERG Biky Cross Grey Handbrake | C31: 8715839085365 | E31: NVT | F31: NVT | G31: NVT | H31: NVT | I31: NVT | N31: =O31/1.5 -> 103.33333 | O31: 155 | P31: NVT | Q31: =Q28+30 -> 316.8 | R31: =Q31/7.6 -> 41.684211 | S31: NVT | T31: =N31/R31 -> 2.4789562 | U31: NVT | Z31: NVT | AA31: NVT | AB31: 1550 | AC31: =N31*AB31 -> 160166.67 | AD31: NVT | AE31: NVT
B32: BERG BeachWagon
A33: 18.07.10.01 | B33: BERG Beach Wagon L | C33: 8715839045222 | E33: =F33/1.5 -> 159.33333 | F33: 239 | H33: =35.74+37 -> 72.74 | I33: =E33/H33 -> 2.19045 | J33: =VLOOKUP(A33,Mastersheet!$A:$AK,30,0) -> 183.2 | K33: =VLOOKUP(A33,Mastersheet!$A:$AK,32,0) -> 151.83 | L33: =VLOOKUP(A33,Mastersheet!$A:$AK,34,0) -> 121.92 | N33: =O33/1.5 -> 190 | O33: 285 | P33: =(R33-H33)/(H33) -> 0.11850426 | R33: =40.36+41 -> 81.36 | S33: =O33-F33 -> 46 | T33: =N33/R33 -> 2.3352999 | U33: =T33-I33 -> 0.1448499 | W33: 0 | X33: 0 | Y33: 0 | Z33: =S33/F33 -> 0.19246862 | AA33: =13000/AC33 -> 0.044142615 | AB33: 1550 | AC33: =N33*AB33 -> 294500
A34: 18.07.17.01 | B34: BERG Beach Wagon XL | C34: 8715839045208 | E34: =F34/1.5 -> 179.33333 | F34: 269 | H34: =35.74+47 -> 82.74 | I34: =E34/H34 -> 2.1674321 | J34: =VLOOKUP(A34,Mastersheet!$A:$AK,30,0) -> 207.2 | K34: =VLOOKUP(A34,Mastersheet!$A:$AK,32,0) -> 170.12 | L34: =VLOOKUP(A34,Mastersheet!$A:$AK,34,0) -> 139.42 | N34: =O34/1.5 -> 216.66667 | O34: 325 | P34: =(R34-H34)/(H34) -> 0.11626783 | R34: =40.36+52 -> 92.36 | S34: =O34-F34 -> 56 | T34: =N34/R34 -> 2.3458929 | U34: =T34-I34 -> 0.17846077 | W34: 0 | X34: 0 | Y34: 0 | Z34: =S34/F34 -> 0.20817844 | AA34: =13000/AC34 -> 0.038709677 | AB34: 1550 | AC34: =N34*AB34 -> 335833.33
B35: BERG Accessoires
A36: 16.00.01.00 | B36: BERG Carrying Strap | C36: 8715839065749 | E36: =F36/1.5 -> 6.6666667 | F36: 10 | G36: 18 | H36: =G36/7.85 -> 2.2929936 | I36: =E36/H36 -> 2.9074074 | J36: =VLOOKUP(A36,Mastersheet!$A:$AK,30,0) -> #N/A | K36: =VLOOKUP(A36,Mastersheet!$A:$AK,32,0) -> #N/A | L36: =VLOOKUP(A36,Mastersheet!$A:$AK,34,0) -> #N/A | N36: =O36/1.5 -> 9.3333333 | O36: 14 | P36: =(Q36-G36)/(G36) -> 0 | Q36: 18 | R36: =Q36/7.6 -> 2.3684211 | S36: =O36-F36 -> 4 | T36: =N36/R36 -> 3.9407407 | U36: =T36-I36 -> 1.0333333 | W36: 0 | X36: 0 | Y36: 0 | Z36: =S36/F36 -> 0.4 | AA36: =13000/AC36 -> 0.89861751 | AB36: 1550 | AC36: =N36*AB36 -> 14466.667
A37: 16.50.00.00 | B37: BERG Push Handle XS | C37: 8715839065725 | E37: =F37/1.5 -> 16.666667 | F37: 25 | G37: 50 | H37: =G37/7.85 -> 6.3694268 | I37: =E37/H37 -> 2.6166667 | J37: =VLOOKUP(A37,Mastersheet!$A:$AK,30,0) -> #N/A | K37: =VLOOKUP(A37,Mastersheet!$A:$AK,32,0) -> #N/A | L37: =VLOOKUP(A37,Mastersheet!$A:$AK,34,0) -> #N/A | N37: =O37/1.5 -> 19.333333 | O37: 29 | P37: =(Q37-G37)/(G37) -> 0.1 | Q37: 55 | R37: =Q37/7.6 -> 7.2368421 | S37: =O37-F37 -> 4 | T37: =N37/R37 -> 2.6715152 | U37: =T37-I37 -> 0.054848485 | W37: 0 | X37: 0 | Y37: 0 | Z37: =S37/F37 -> 0.16 | AA37: =13000/AC37 -> 0.43381535 | AB37: 1550 | AC37: =N37*AB37 -> 29966.667
A38: 16.00.00.00 | B38: BERG Safety Flag XS | C38: 8715839065732 | E38: =F38/1.5 -> 8.3333333 | F38: 12.5 | G38: 17.6 | H38: =G38/7.85 -> 2.2420382 | I38: =E38/H38 -> 3.7168561 | J38: =VLOOKUP(A38,Mastersheet!$A:$AK,30,0) -> #N/A | K38: =VLOOKUP(A38,Mastersheet!$A:$AK,32,0) -> #N/A | L38: =VLOOKUP(A38,Mastersheet!$A:$AK,34,0) -> #N/A | N38: =O38/1.5 -> 10.666667 | O38: 16 | P38: =(Q38-G38)/(G38) -> 0.1 | Q38: 19.36 | R38: =Q38/7.6 -> 2.5473684 | S38: =O38-F38 -> 3.5 | T38: =N38/R38 -> 4.1873278 | U38: =T38-I38 -> 0.47047176 | W38: 0 | X38: 0 | Y38: 0 | Z38: =S38/F38 -> 0.28 | AA38: =13000/AC38 -> 0.78629032 | AB38: 1550 | AC38: =N38*AB38 -> 16533.333
A39: 16.00.04.00 | B39: BERG Helmet S | C39: 8715839078909 | E39: =F39/1.5 -> 12.666667 | F39: 19 | G39: 45 | H39: =G39/7.85 -> 5.7324841 | I39: =E39/H39 -> 2.2096296 | N39: =O39/1.5 -> 18.333333 | O39: 27.5 | P39: =(Q39-G39)/(G39) -> 0 | Q39: 45 | R39: =Q39/7.6 -> 5.9210526 | S39: =O39-F39 -> 8.5 | T39: =N39/R39 -> 3.0962963 | U39: =T39-I39 -> 0.88666667 | Z39: =S39/F39 -> 0.44736842 | AA39: =13000/AC39 -> 0.45747801 | AB39: 1550 | AC39: =N39*AB39 -> 28416.667
A40: 16.00.05.00 | B40: BERG Biky Protection Cushion | C40: 8715839078916 | E40: =F40/1.5 -> 3.3333333 | F40: 5 | G40: 7.4 | H40: =G40/7.85 -> 0.94267516 | I40: =E40/H40 -> 3.536036 | N40: =O40/1.5 -> 7.3333333 | O40: 11 | P40: =(Q40-G40)/(G40) -> 0.13513514 | Q40: 8.4 | R40: =Q40/7.6 -> 1.1052632 | S40: =O40-F40 -> 6 | T40: =N40/R40 -> 6.6349206 | U40: =T40-I40 -> 3.0988846 | Z40: =S40/F40 -> 1.2 | AA40: =13000/AC40 -> 1.143695 | AB40: 1550 | AC40: =N40*AB40 -> 11366.667
A41: 16.00.06.00 | B41: BERG Biky Kickstand | C41: 8715839078923 | E41: =F41/1.5 -> 8.3333333 | F41: 12.5 | G41: 24.5 | H41: =G41/7.85 -> 3.1210191 | I41: =E41/H41 -> 2.670068 | N41: =O41/1.5 -> 10.666667 | O41: 16 | P41: =(Q41-G41)/(G41) -> 0 | Q41: 24.5 | R41: =Q41/7.6 -> 3.2236842 | S41: =O41-F41 -> 3.5 | T41: =N41/R41 -> 3.3088435 | U41: =T41-I41 -> 0.63877551 | Z41: =S41/F41 -> 0.28 | AA41: =13000/AC41 -> 0.78629032 | AB41: 1550 | AC41: =N41*AB41 -> 16533.333
A42: 16.00.07.00 | B42: BERG Biky Safety Flag | C42: 8715839078930 | E42: =F42/1.5 -> 8.3333333 | F42: 12.5 | G42: 20 | H42: =G42/7.85 -> 2.5477707 | I42: =E42/H42 -> 3.2708333 | N42: =O42/1.5 -> 10.666667 | O42: 16 | P42: =(Q42-G42)/(G42) -> 0.1 | Q42: 22 | R42: =Q42/7.6 -> 2.8947368 | S42: =O42-F42 -> 3.5 | T42: =N42/R42 -> 3.6848485 | U42: =T42-I42 -> 0.41401515 | Z42: =S42/F42 -> 0.28 | AA42: =13000/AC42 -> 0.78629032 | AB42: 1550 | AC42: =N42*AB42 -> 16533.333
...

Sheet Nieuw AX
A1: Item number | B1: Product name | C1: Vendor | D1: Freight allocation group | E1: Visible in webshop | F1: Commission item group | G1: Alternative item number | H1: When to use | I1: Kit | J1: Item rebate group | K1: Coverage group | L1: Country/region | M1: Pallet quantity | N1: E-commerce | O1: Volume | P1: Net weight | Q1: Tare weight | R1: Gross width | S1: Gross depth | T1: Gross height | U1: Commodity | V1: Danger class | W1: Search name | X1: Total weight | Y1: Extended fieldcheck RT-WMS | Z1: Product type | AA1: Product subtype | AB1: Product dimension group | AC1: Production type
A2: 35.09.01.02 | B2: BERG Favorit 270 (9 ft) + Safety Net Comfort | D2: UNDER_CON | E2: No | H2: Never | I2: Yes | J2: IMPOSSIBLE | K2: TRAMPO | M2: 1 | N2: No | O2: 1 | P2: 0.01 | Q2: 0 | R2: 1 | S2: 1 | T2: 1 | W2: 35090102 | Y2: Enabled | Z2: Item | AA2: Product | AC2: BOM
A3: 35.09.05.01 | B3: BERG InGround Favorit 270 (9 ft) + Safety Net Comfort | D3: UNDER_CON | E3: No | H3: Never | I3: Yes | J3: IMPOSSIBLE | K3: TRAMPO | M3: 1 | N3: No | O3: 1 | P3: 0.01 | Q3: 0 | R3: 1 | S3: 1 | T3: 1 | W3: 35090501 | Y3: Enabled | Z3: Item | AA3: Product | AC3: BOM
A4: 35.11.01.02 | B4: BERG Favorit 330 (11 ft) + Safety Net Comfort | D4: UNDER_CON | E4: No | H4: Never | I4: Yes | J4: IMPOSSIBLE | K4: TRAMPO | M4: 1 | N4: No | O4: 1 | P4: 0.01 | Q4: 0 | R4: 1 | S4: 1 | T4: 1 | W4: 35110102 | Y4: Enabled | Z4: Item | AA4: Product | AC4: BOM
A5: 35.11.04.01 | B5: BERG InGround Favorit 330 (11 ft) + Safety Net Comfort | D5: UNDER_CON | E5: No | H5: Never | I5: Yes | J5: IMPOSSIBLE | K5: TRAMPO | M5: 1 | N5: No | O5: 1 | P5: 0.01 | Q5: 0 | R5: 1 | S5: 1 | T5: 1 | W5: 35110401 | Y5: Enabled | Z5: Item | AA5: Product | AC5: BOM
A6: 35.11.92.00 | B6: BERG InGround Favorit Grey 330 + Safety Net Comfort | D6: UNDER_CON | E6: No | H6: Never | I6: Yes | J6: PENDING | K6: TRAMPO | M6: 1 | N6: No | O6: 1 | P6: 0.01 | Q6: 0 | R6: 1 | S6: 1 | T6: 1 | W6: 35119200 | Y6: Enabled | Z6: Item | AA6: Product | AC6: BOM
A7: 35.11.94.00 | B7: BERG Favorit Grey 330 + Safety Net Comfort | D7: UNDER_CON | E7: No | H7: Never | I7: Yes | J7: PENDING | K7: TRAMPO | M7: 1 | N7: No | O7: 1 | P7: 0.01 | Q7: 0 | R7: 1 | S7: 1 | T7: 1 | W7: 35119400 | Y7: Enabled | Z7: Item | AA7: Product | AC7: BOM
A8: 35.12.01.02 | B8: BERG Favorit 380 (12,5 ft) + Safety Net Comfort | D8: UNDER_CON | E8: No | H8: Never | I8: Yes | J8: IMPOSSIBLE | K8: TRAMPO | M8: 1 | N8: No | O8: 1 | P8: 0.01 | Q8: 0 | R8: 1 | S8: 1 | T8: 1 | W8: 35120102 | Y8: Enabled | Z8: Item | AA8: Product | AC8: BOM
A9: 35.12.04.01 | B9: BERG InGround Favorit 380 (12,5 ft) + Safety Net Comfort | D9: UNDER_CON | E9: No | H9: Never | I9: Yes | J9: IMPOSSIBLE | K9: TRAMPO | M9: 1 | N9: No | O9: 1 | P9: 0.01 | Q9: 0 | R9: 1 | S9: 1 | T9: 1 | W9: 35120401 | Y9: Enabled | Z9: Item | AA9: Product | AC9: BOM
A10: 35.12.92.00 | B10: BERG InGround Favorit Grey 380 + Safety Net Comfort | D10: UNDER_CON | E10: No | H10: Never | I10: Yes | J10: PENDING | K10: TRAMPO | M10: 1 | N10: No | O10: 1 | P10: 0.01 | Q10: 0 | R10: 1 | S10: 1 | T10: 1 | W10: 35129200 | Y10: Enabled | Z10: Item | AA10: Product | AC10: BOM
A11: 35.12.94.00 | B11: BERG Favorit Grey 380 + Safety Net Comfort | D11: UNDER_CON | E11: No | H11: Never | I11: Yes | J11: PENDING | K11: TRAMPO | M11: 1 | N11: No | O11: 1 | P11: 0.01 | Q11: 0 | R11: 1 | S11: 1 | T11: 1 | W11: 35129400 | Y11: Enabled | Z11: Item | AA11: Product | AC11: BOM
A12: 35.14.02.02 | B12: BERG Favorit 430 (14 ft) + Safety Net Comfort | D12: UNDER_CON | E12: No | H12: Never | I12: Yes | J12: IMPOSSIBLE | K12: TRAMPO | M12: 1 | N12: No | O12: 1 | P12: 0.01 | Q12: 0 | R12: 1 | S12: 1 | T12: 1 | W12: 35140202 | Y12: Enabled | Z12: Item | AA12: Product | AC12: BOM
A13: 35.14.03.02 | B13: BERG Favorit 430 (14 ft) Tattoo + Safety Net Comfort | D13: UNDER_CON | E13: No | H13: Never | I13: Yes | J13: IMPOSSIBLE | K13: TRAMPO | M13: 1 | N13: No | O13: 1 | P13: 0.01 | Q13: 0 | R13: 1 | S13: 1 | T13: 1 | W13: 35140302 | Y13: Enabled | Z13: Item | AA13: Product | AC13: BOM
... A16: 35.14.94.00 | B16: BERG Favorit Grey 430 + Safety Net Comfort | D16: UNDER_CON | E16: No | H16: Never | I16: Yes | J16: PENDING | K16: TRAMPO | M16: 1 | N16: No | O16: 1 | P16: 0.01 | Q16: 0 | R16: 1 | S16: 1 | T16: 1 | W16: 35149400 | Y16: Enabled | Z16: Item | AA16: Product | AC16: BOM
A17: 35.39.01.02 | B17: BERG Champion 270 + Safety Net Deluxe | D17: UNDER_CON | E17: No | H17: Never | I17: Yes | J17: IMPOSSIBLE | K17: TRAMPO | L17: CHN | M17: 6 | N17: No | O17: 1 | P17: 76.3 | Q17: 0 | R17: 1 | S17: 1 | T17: 1 | U17: 95069190 | W17: 35390102 | Y17: Enabled | Z17: Item | AA17: Product | AC17: BOM
A18: 35.39.04.01 | B18: BERG Champion 270 + Safety Net Comfort | D18: UNDER_CON | E18: No | H18: Never | I18: Yes | J18: IMPOSSIBLE | K18: TRAMPO | L18: CHN | M18: 6 | N18: No | O18: 1 | P18: 69.3 | Q18: 0 | R18: 1 | S18: 1 | T18: 1 | U18: 95069190 | W18: 35390401 | Y18: Enabled | Z18: Item | AA18: Product | AC18: BOM
A19: 35.39.05.01 | B19: BERG InGround Champion 270 + Safety Net Deluxe | D19: UNDER_CON | E19: No | H19: Never | I19: Yes | J19: IMPOSSIBLE | K19: TRAMPO | L19: CHN | M19: 6 | N19: No | O19: 1 | P19: 73.6 | Q19: 0 | R19: 1 | S19: 1 | T19: 1 | U19: 95069190 | W19: 35390501 | Y19: Enabled | Z19: Item | AA19: Product | AC19: BOM
A20: 35.39.06.01 | B20: BERG InGround Champion 270 + Safety Net Comfort | D20: UNDER_CON | E20: No | H20: Never | I20: Yes | J20: IMPOSSIBLE | K20: TRAMPO | L20: CHN | M20: 6 | N20: No | O20: 1 | P20: 66.7 | Q20: 0 | R20: 1 | S20: 1 | T20: 1 | U20: 95069190 | W20: 35390601 | Y20: Enabled | Z20: Item | AA20: Product | AC20: BOM
A21: 35.41.01.02 | B21: BERG Champion 330 + Safety Net Deluxe | D21: UNDER_CON | E21: No | H21: Never | I21: Yes | J21: IMPOSSIBLE | K21: TRAMPO | L21: CHN | M21: 6 | N21: No | O21: 1 | P21: 113.7 | Q21: 0 | R21: 1 | S21: 1 | T21: 1 | U21: 95069190 | W21: 35410102 | Y21: Enabled | Z21: Item | AA21: Product | AC21: BOM
A22: 35.41.04.01 | B22: BERG Champion 330 + Safety Net Comfort | D22: UNDER_CON | E22: No | H22: Never | I22: Yes | J22: IMPOSSIBLE | K22: TRAMPO | L22: CHN | M22: 6 | N22: No | O22: 1 | P22: 101.1 | Q22: 0 | R22: 1 | S22: 1 | T22: 1 | U22: 95069190 | W22: 35410401 | Y22: Enabled | Z22: Item | AA22: Product | AC22: BOM
A23: 35.41.05.01 | B23: BERG InGround Champion 330 + Safety Net Deluxe | D23: UNDER_CON | E23: No | H23: Never | I23: Yes | J23: IMPOSSIBLE | K23: TRAMPO | L23: CHN | M23: 6 | N23: No | O23: 1 | P23: 98.8 | Q23: 0 | R23: 1 | S23: 1 | T23: 1 | U23: 95069190 | W23: 35410501 | Y23: Enabled | Z23: Item | AA23: Product | AC23: BOM
A24: 35.41.06.01 | B24: BERG InGround Champion 330 + Safety Net Comfort | D24: UNDER_CON | E24: No | H24: Never | I24: Yes | J24: IMPOSSIBLE | K24: TRAMPO | L24: CHN | M24: 6 | N24: No | O24: 1 | P24: 86.5 | Q24: 0 | R24: 1 | S24: 1 | T24: 1 | U24: 95069190 | W24: 35410601 | Y24: Enabled | Z24: Item | AA24: Product | AC24: BOM
A25: 35.41.80.00 | B25: BERG Champion USA 11ft + BERG Safety Net Deluxe USA | D25: UNDER_CON | E25: No | H25: Never | I25: Yes | J25: IMPOSSIBLE | K25: TRAMPO | M25: 1 | N25: No | O25: 1 | P25: 0.01 | Q25: 0 | R25: 1 | S25: 1 | T25: 1 | W25: 35418000 | Y25: Enabled | Z25: Item | AA25: Product | AC25: BOM
